Workbook

Sheet Export Summary
B3: This document was exported from Numbers. Each table was converted to an Excel worksheet. All other objects on each Numbers sheet were placed on separate worksheets. Please be aware that formula calculations may differ in Excel.
B7: Numbers Sheet Name | C7: Numbers Table Name | D7: Excel Worksheet Name
B9: C EGRESOS
C10: Table 1 | D10: C EGRESOS
B11: EDO R
C12: Table 1 | D12: EDO R
B13: INGRESOS
C14: Table 1 | D14: INGRESOS
B15: EGRESOS
C16: Table 1 | D16: EGRESOS
B17: ENERO
C18: Table 1 | D18: ENERO
B19: FEBRERO
C20: Table 1 | D20: FEBRERO
B21: MARZO
C22: Table 1 | D22: MARZO
B23: ABRIL
C24: Table 1 | D24: ABRIL
B25: MAYO
C26: Table 1 | D26: MAYO
B27: JUNIO
C28: Table 1 | D28: JUNIO
B29: JULIO
C30: Table 1 | D30: JULIO
B31: AGOSTO
C32: Table 1 | D32: AGOSTO
B33: SEPTIEMBRE
C34: Table 1 | D34: SEPTIEMBRE
B35: OCTUBRE
C36: Table 1 | D36: OCTUBRE
B37: NOVIEMBRE
C38: Table 1 | D38: NOVIEMBRE
B39: DICIEMBRE
C40: Table 1 | D40: DICIEMBRE

Sheet C EGRESOS
B2: CONSTRUYENDO LAZOS LA ESTANZUELA 2025
B3: CTA. 1385
D6: ENERO | E6: FEBRERO | F6: MARZO | G6: ABRIL | H6: MAYO | I6: JUNIO | J6: JULIO | K6: AGOSTO | L6: SEPTIEMBRE | M6: OCTUBRE | N6: NOVIEMBRE | O6: DICIEMBRE
B7: C/n. Atend | C7: 1400 | D7: {='EGRESOS'!H25} -> 1400 | E7: {='EGRESOS'!H56} -> 0 | F7: {='EGRESOS'!H98} -> 0 | G7: {='EGRESOS'!H130} -> 0 | H7: {='EGRESOS'!H155} -> 0 | I7: {='EGRESOS'!H191} -> 0 | J7: {='EGRESOS'!H218} -> 0 | K7: {='EGRESOS'!H242} -> 0 | L7: {='EGRESOS'!H275} -> 0 | M7: {='EGRESOS'!H300} -> 0
B8: honorarios | C8: 4640 | D8: {='EGRESOS'!I25} -> 0 | E8: {='EGRESOS'!I56} -> 0 | F8: {='EGRESOS'!I98} -> 4640 | G8: {='EGRESOS'!I130} -> 0 | H8: {='EGRESOS'!I155} -> 0 | I8: {='EGRESOS'!I191} -> 0 | J8: {='EGRESOS'!I218} -> 0 | K8: {='EGRESOS'!I242} -> 0 | L8: {='EGRESOS'!I275} -> 0 | M8: {='EGRESOS'!I300} -> 0
B9: C Anual | C9: 6032 | D9: {='EGRESOS'!J25} -> 6032 | E9: {='EGRESOS'!J56} -> 0 | F9: {='EGRESOS'!J98} -> 0 | G9: {='EGRESOS'!J130} -> 0 | H9: {='EGRESOS'!J155} -> 0 | I9: {='EGRESOS'!J191} -> 0 | J9: {='EGRESOS'!J218} -> 0 | K9: {='EGRESOS'!J242} -> 0 | L9: {='EGRESOS'!J275} -> 0 | M9: {='EGRESOS'!J300} -> 0
B10: Imss | C10: 13272.32 | D10: {='EGRESOS'!K25} -> 0 | E10: {='EGRESOS'!K56} -> 0 | F10: {='EGRESOS'!K98} -> 13272.32 | G10: {='EGRESOS'!K130} -> 0 | H10: {='EGRESOS'!K155} -> 0 | I10: {='EGRESOS'!K191} -> 0 | J10: {='EGRESOS'!K218} -> 0 | K10: {='EGRESOS'!K242} -> 0 | L10: {='EGRESOS'!K275} -> 0 | M10: {='EGRESOS'!K300} -> 0
B11: Sat | C11: 9340 | D11: {='EGRESOS'!L25} -> 4570 | E11: {='EGRESOS'!L56} -> 0 | F11: {='EGRESOS'!L98} -> 4770 | G11: {='EGRESOS'!L130} -> 0 | H11: {='EGRESOS'!L155} -> 0 | I11: {='EGRESOS'!L191} -> 0 | J11: {='EGRESOS'!L218} -> 0 | K11: {='EGRESOS'!L242} -> 0 | L11: {='EGRESOS'!L275} -> 0 | M11: {='EGRESOS'!L300} -> 0
B12: Nómina | C12: 266130.7 | D12: {='EGRESOS'!M25} -> 14000.42 | E12: {='EGRESOS'!M56} -> 28062.04 | F12: {='EGRESOS'!M98} -> 27975.21 | G12: {='EGRESOS'!M130} -> 28004.16 | H12: {='EGRESOS'!M155} -> 31677.31 | I12: {='EGRESOS'!M191} -> 28415.15 | J12: {='EGRESOS'!M218} -> 26541.83 | K12: {='EGRESOS'!M242} -> 26975.21 | L12: {='EGRESOS'!M275} -> 27004.16 | M12: {='EGRESOS'!M300} -> 27475.21
B13: traspaso | C13: 461850 | D13: {='EGRESOS'!N25} -> 75000 | E13: {='EGRESOS'!N56} -> 20000 | F13: {='EGRESOS'!M98} -> 27975.21 | G13: {='EGRESOS'!N130} -> 147850 | H13: {='EGRESOS'!N155} -> 10000 | I13: {='EGRESOS'!N191} -> 0 | J13: {='EGRESOS'!N218} -> 100000 | K13: {='EGRESOS'!N242} -> 0 | L13: {='EGRESOS'!N275} -> 0 | M13: {='EGRESOS'!N300} -> 15000
B14: Comisiones | C14: 42409.98 | D14: {='EGRESOS'!O25} -> 3596.68 | E14: {='EGRESOS'!O56} -> 4034.73 | F14: {='EGRESOS'!N98} -> 94000 | G14: {='EGRESOS'!O130} -> 2490.67 | H14: {='EGRESOS'!O155} -> 2109.18 | I14: {='EGRESOS'!N191} -> 0 | J14: {='EGRESOS'!O218} -> 2626.86 | K14: {='EGRESOS'!O242} -> 2344.63 | L14: {='EGRESOS'!O275} -> 15620.26 | M14: {='EGRESOS'!O300} -> 1659.53
B15: Iva. Com | C15: 4810.72 | D15: {='EGRESOS'!P25} -> 575.44 | E15: {='EGRESOS'!P56} -> 645.53 | F15: {='EGRESOS'!O98} -> 4372.33 | G15: {='EGRESOS'!P130} -> 878.75 | H15: {='EGRESOS'!P155} -> 337.46 | I15: {='EGRESOS'!O191} -> 3555.11 | J15: {='EGRESOS'!P218} -> 369.85 | K15: {='EGRESOS'!P242} -> 169.7 | L15: {='EGRESOS'!P275} -> 373.72 | M15: {='EGRESOS'!P300} -> 277.12
B16: papelería | C16: 18623.46 | D16: {='EGRESOS'!Q25} -> 0 | E16: {='EGRESOS'!Q56} -> 3233.42 | F16: {='EGRESOS'!P98} -> 606.75 | G16: {='EGRESOS'!Q130} -> 0 | H16: {='EGRESOS'!Q155} -> 0 | I16: {='EGRESOS'!P191} -> 576.4 | J16: {='EGRESOS'!Q218} -> 0 | K16: {='EGRESOS'!Q242} -> 0 | L16: {='EGRESOS'!Q275} -> 1100 | M16: {='EGRESOS'!Q300} -> 4640
B17: campaña | C17: 231360 | D17: {='EGRESOS'!R25} -> 0 | E17: {='EGRESOS'!R56} -> 17400 | F17: {='EGRESOS'!Q98} -> 2683.54 | G17: {='EGRESOS'!R130} -> 120000 | H17: {='EGRESOS'!R155} -> 0 | I17: {='EGRESOS'!Q191} -> 6966.5 | J17: {='EGRESOS'!R218} -> 0 | K17: {='EGRESOS'!R242} -> 0 | L17: {='EGRESOS'!R275} -> 0 | M17: {='EGRESOS'!R300} -> 0
B18: Mtto.Mob y Eq | C18: 79554.35 | D18: {='EGRESOS'!S25} -> 0 | E18: {='EGRESOS'!S56} -> 0 | F18: {='EGRESOS'!R98} -> 93960 | G18: {='EGRESOS'!S130} -> 54896.4 | H18: {='EGRESOS'!S155} -> 24657.95 | I18: {='EGRESOS'!R191} -> 0 | J18: {='EGRESOS'!S218} -> 0 | K18: {='EGRESOS'!S242} -> 0 | L18: {='EGRESOS'!S275} -> 0 | M18: {='EGRESOS'!S300} -> 0
B19: Mtto. Edificio | C19: 509610.18 | D19: {='EGRESOS'!U25} -> 0 | E19: {='EGRESOS'!T56} -> 0 | F19: {='EGRESOS'!S98} -> 0 | G19: {='EGRESOS'!S130} -> 54896.4 | H19: {='EGRESOS'!T155} -> 0 | I19: {='EGRESOS'!S191} -> 0 | J19: {='EGRESOS'!T218} -> 217453.6 | K19: {='EGRESOS'!T242} -> 35011.03 | L19: {='EGRESOS'!T275} -> 213645.55 | M19: {='EGRESOS'!T300} -> 43500
B20: Seguros Autos | C20: 40405.1 | D20: {='EGRESOS'!U25} -> 0 | E20: {='EGRESOS'!U56} -> 0 | F20: {='EGRESOS'!T98} -> 0 | G20: {='EGRESOS'!T130} -> 0 | H20: {='EGRESOS'!U155} -> 0 | I20: {='EGRESOS'!T191} -> 0 | J20: {='EGRESOS'!U218} -> 0 | K20: {='EGRESOS'!U242} -> 30535.26 | L20: {='EGRESOS'!U275} -> 9869.84 | M20: {='EGRESOS'!U300} -> 0
B21: Varios | C21: 246346 | D21: {='EGRESOS'!V25} -> 0 | E21: {='EGRESOS'!V56} -> 0 | F21: {='EGRESOS'!W56} -> 0 | G21: {='EGRESOS'!U130} -> 0 | H21: {='EGRESOS'!V155} -> 0 | I21: {='EGRESOS'!V191} -> 0 | J21: {='EGRESOS'!V218} -> 0 | K21: {='EGRESOS'!V242} -> 0 | L21: {='EGRESOS'!V275} -> 90860 | M21: {='EGRESOS'!V300} -> 155486
B22: Mtto eq. Ofna | C22: 12617.91 | D22: {='EGRESOS'!W25} -> 0 | E22: {='EGRESOS'!X25} -> 105174.54 | F22: {='EGRESOS'!Y25} -> 0 | G22: {='EGRESOS'!W130} -> 0 | H22: {='EGRESOS'!W155} -> 0 | I22: {='EGRESOS'!W191} -> 0 | J22: {='EGRESOS'!W218} -> 0 | K22: {='EGRESOS'!W242} -> 0 | L22: {='EGRESOS'!W275} -> 0 | M22: {='EGRESOS'!W300} -> 12617.91
C23: {=SUM(C7:C22)} -> 1948402.7 | D23: {=SUM(D7:D22)} -> 105174.54 | E23: {=SUM(E7:E22)} -> 178550.26 | F23: {=SUM(F7:F22)} -> 274255.36 | G23: {=SUM(G7:G22)} -> 409016.38 | H23: {=SUM(H7:H22)} -> 68781.9 | I23: {=SUM(I7:I22)} -> 39513.16 | J23: {=SUM(J7:J22)} -> 346992.14 | ... O23: {=SUM(O7:O22)} -> 0

Sheet EDO R
B2: CONTRUYENDO LAZOS LA ESTANZUELA ESTADO DE RESULTADOS ENERO A OCTUBRE 17 DEL 2025
C3: 1385 | D3: Totales | E3: C/individuales | F3: C Tarjeta | G3: Efectivo | H3: Varios
B4: TOTAL DE INGRESOS | D4: {=E4+F4+G4+H4+I4} -> 1352584.8 | E4: 71550 | F4: 1117300 | G4: 119950 | H4: 43784.83 | I4: 0
B7: C/n. Atend | C7: 1400 | G7: 1400
B8: honorarios | C8: 4640 | G8: 4640
B9: C Anual | C9: 6032 | G9: {=C9} -> 6032
B10: Imss | C10: 13272.32 | G10: {=C10} -> 13272.32
B11: Sat | C11: 9340 | G11: {=C11} -> 9340
B12: Nómina | C12: 266130.7 | F12: {=C12} -> 266130.7
B13: traspaso | C13: 461850 | F13: {=C13} -> 461850
B14: Comisiones | C14: 42409.98 | G14: {=C14} -> 42409.98
B15: Iva. Com | C15: 4810.72 | G15: {=C15} -> 4810.72
B16: papelería | C16: 18623.46 | G16: {=C16} -> 18623.46
B17: campaña | C17: 231360 | F17: {=C17} -> 231360
B18: Mtto.Mob y Eq | C18: 79554.35 | F18: {=C18} -> 79554.35
B19: Mtto. Edificio | C19: 509610.18 | F19: {=C19} -> 509610.18
B20: Seguros Autos | C20: 40405.1 | H20: {=C20} -> 40405.1
B21: Varios | C21: 246346 | F21: {=C21} -> 246346
B22: Mtto eq. Ofna | C22: 12617.91 | G22: 7466.78
C23: {=SUM(C7:C22)} -> 1948402.7 | F23: {=SUM(F6:F22)} -> 1794851.2 | G23: {=SUM(G6:G22)} -> 107995.26 | H23: {=SUM(H6:H22)} -> 40405.1
C27: Diferencias | D27: Saldo positivo | E27: {=D25+G25} -> 0
D28: Saldo negativo | E28: {=E25+F25+H25+I25+J25+K25+L25} -> 0
D29: SALDO E CTA

Sheet INGRESOS
C2: CONSTRUYENDO LAZOS LA ESTANZUELA 2025
B3: Libro de Entradas y Salidas Correspondiente al Mes de Enero 2025
C4: Concepto CTA 1385 | D4: BANCOS | F4: Bancos | G4: Bancos
B5: Folio/ Cheque | D5: NOTARIA | F5: TRANSFER | G5: EFECTIVO | H5: Totales | I5: C/individuales | J5: C Tarjeta | K5: Efectivo | L5: Varios
B6: INGRESO | E6: TRANSFERENCIA | H6: {=G27+F27} -> 185250.05
C7: 1554 | D7: APORTACION DE MIEMBROS | E7: MARIA ZENAIDA VAZQUEZ | F7: 500 | I7: {=F7} -> 500
D8: APORTACION DE MIEMBROS | E8: VENTA TPVDB 09346260 | F8: 500 | J8: {=F8} -> 500
D9: APORTACION DE MIEMBROS | E9: VERONICA ILEANA CARRILLO | F9: 500 | I9: {=F9} -> 500
C10: 1557 | D10: APORTACION DE MIEMBROS | E10: LUCIA TAHUIL RODRIGUEZ | F10: 200 | I10: {=F10} -> 200
D11: APORTACION DE MIEMBROS | E11: YOLANDA VILLEDA | G11: 500 | K11: {=G11} -> 500
D12: APORTACION DE MIEMBROS | E12: MAGNOLIA VILLEDA | G12: 500 | K12: {=G12} -> 500
D13: APORTACION DE MIEMBROS | E13: LETY VIDALES | G13: 5250 | K13: {=G13} -> 5250
C14: 1553 | D14: APORTACION DE MIEMBROS | E14: JOSÉ DE JESÚS MARRUSOU | F14: 500 | I14: {=F14} -> 500
D15: APORTACION DE MIEMBROS | E15: VENTA TPVDB9346260 | F15: 107300 | J15: {=F15} -> 107300
D16: APORTACION DE MIEMBROS | E16: VENTA TPVDB9346260 | F16: 28450 | J16: {=F16} -> 28450
D17: APORTACION DE MIEMBROS | E17: VENTA TPVDB9346260 | F17: 28250 | J17: {=F17} -> 28250
D18: APORTACION DE MIEMBROS | E18: COMPENSACION DE SPEI | F18: 0.05 | L18: {=F18} -> 0.05
C19: 1552 | D19: APORTACION DE MIEMBROS | E19: SAIDE LISSETTE GUERRERO A | F19: 500 | I19: {=F19} -> 500
C20: 1551 | D20: APORTACION DE MIEMBROS | E20: OSCAR GONZÁLEZ ALANIS | F20: 1000 | I20: {=F20} -> 1000
D21: APORTACION DE MIEMBROS | E21: VENTA TPVDB9346260 | F21: 600 | J21: {=F21} -> 600
D22: APORTACION DE MIEMBROS | E22: MARTHA MEZA | G22: 1000 | J22: {=G22} -> 1000
D23: APORTACION DE MIEMBROS | E23: MARIO LÓPEZ ALATORRE | F23: 500 | I23: {=F23} -> 500
D24: APORTACION DE MIEMBROS | E24: DOLORES GUERVARA LÓPEZ Y NORA | G24: 3000 | K24: {=G24} -> 3000
D25: APORTACION DE MIEMBROS | E25: LUCIA TAHUIL RODRIGUEZ | F25: 200 | I25: {=F25} -> 200
D26: APORTACION DE MIEMBROS | E26: DENTISTAS ESPECIALIZADOS MONTERREY | F26: 6000 | I26: {=F26} -> 6000
F27: {=SUM(F7:F26)} -> 175000.05 | G27: {=SUM(G7:G26)} -> 10250 | I27: {=SUM(I7:I26)} -> 9900 | J27: {=SUM(J7:J26)} -> 166100 | K27: {=SUM(K7:K26)} -> 9250 | L27: {=SUM(L7:L26)} -> 0.05
B28: CONSTRUYENDO LAZOS LA ESTANZUELA AC
D30: Concepto CTA | E30: BANCOS
B31: Fecha | C31: Folio/ Cheque | E31: NOTARIA
C32: INGRESO | F32: TRANSFERENCIA | G32: EFECTIVO | H32: {=F48+G48} -> 172416.71
B33: 45692 | D33: APORTACION DE MIEMBROS | E33: VERÓNICA ILEANA CARRILLO ORTIZ | F33: 500 | I33: {=F33} -> 500
B34: 45693 | D34: APORTACION DE MIEMBROS | E34: MARTHA MEZA | F34: 500 | I34: {=F34} -> 500
B35: 45698 | D35: APORTACION DE MIEMBROS | E35: DEV. DE PAGO P/N0 COMP. RASTREO | F35: 1616.71 | L35: {=F35} -> 1616.71
B36: 45699 | D36: APORTACION DE MIEMBROS | E36: JOSE DE JESÚS MORROSU GARZA | F36: 500 | I36: {=F36} -> 500
B37: 45700 | D37: APORTACION DE MIEMBROS | E37: MARIO LÓPEZ ALATORRE | F37: 500 | I37: {=F37} -> 500
B38: 45705 | D38: APORTACION DE MIEMBROS | E38: VTA TPVCR 9346260 | F38: 24250 | J38: {=F38} -> 24250
B39: 45705 | D39: APORTACION DE MIEMBROS | E39: VTA TPVCR 9346260 | F39: 107150 | J39: {=F39} -> 107150
B40: 45705 | D40: APORTACION DE MIEMBROS | E40: VTA TPVCR 9346260 | F40: 28350 | J40: {=F40} -> 28350
B41: 45705 | D41: APORTACION DE MIEMBROS | E41: DEPOSITO DE EFECTIVO | G41: 500 | K41: {=G41} -> 500
B42: 45705 | D42: APORTACION DE MIEMBROS | E42: MARIA ZENAIDA | F42: 500 | I42: {=F42} -> 500
...

Sheet EGRESOS
B1: CONSTRUYENDO LAZOS LA ESTANZUELA AC
H2: C/n. Atend | I2: honorarios | J2: C Anual | K2: Imss | L2: Sat | M2: Nómina | N2: traspaso | O2: Comisiones | P2: Iva. Com | Q2: papelería | R2: campaña | S2: Mtto.Mob y Eq | T2: Mtto. Edificio | U2: Seguros Autos | V2: Varios | W2: Mtto eq. Ofna
D3: Concepto CTA 1385 AFIRME | E3: BANCOS | G3: BANCOS
B4: Fecha | E4: NOTARIA | G4: CHEQUES
C5: INGRESO
C6: AFIRME | D6: CC NO ATENDIDO 401966 2832 | G6: 700 | H6: {=G6} -> 700
C7: AFIRME | D7: CC NO ATENDIDO 591707 2832 | G7: 700 | H7: {=G7} -> 700
C8: AFIRME | D8: VENTA TPVDB9346260 | G8: 2150.75 | O8: {=G8} -> 2150.75
C9: AFIRME | D9: IVA VENTA TPVDB9346260 | G9: 344.12 | P9: {=G9} -> 344.12
C10: AFIRME | D10: VENTA TPVDB9346260 | G10: 540.55 | O10: {=G10} -> 540.55
C11: AFIRME | D11: IVA VENTA TPVDB9346260 | G11: 86.46 | P11: {=G11} -> 86.46
C12: AFIRME | D12: VENTA TPVDB9346260 | G12: 833.38 | O12: {=G12} -> 833.38
C13: AFIRME | D13: IVA VENTA TPVDB9346260 | G13: 133.34 | P13: {=G13} -> 133.34
C14: SAT | D14: 042507EQ500044844499 | G14: 4570 | L14: {=G14} -> 4570
C15: NOSOTROS MISMOS | D15: DISPERSION DE FONDOS NOM | G15: 14000.42 | M15: {=G15} -> 14000.42
C16: AFIRME | D16: COMISION DE DISPESION DE FONDOS | G16: 10 | O16: {=G16} -> 10
C17: AFIRME | D17: IVA DISPERSION DE FONDOS | G17: 1.6 | P17: {=G17} -> 1.6
C18: JBC CONTADORES PUB Y AUD | D18: CARGO ANUAL | G18: 6032 | J18: {=G18} -> 6032
C19: CONSTRUYENDO LAZOS | D19: TRASPASO ENTRE CUENTAS | G19: 50000 | N19: {=G19} -> 50000
C20: AFIRME | D20: COMISION DE DISPESION DE FONDOS | G20: 12 | O20: {=G20} -> 12
C21: AFIRME | D21: IVA DISPERSION DE FONDOS | G21: 1.92 | P21: {=G21} -> 1.92
C22: CONSTRUYENDO LAZOS | D22: TRASPASO ENTRE CUENTAS | G22: 25000 | N22: {=G22} -> 25000
C23: AFIRME | D23: COMISION ANUALIDAD DEL TOKEN | G23: 50 | O23: {=G23} -> 50
C24: AFIRME | D24: IVA DE COMISION | G24: 8 | P24: {=G24} -> 8
G25: {=SUM(G6:G24)} -> 105174.54 | H25: {=SUM(H6:H24)} -> 1400 | J25: {=SUM(J6:J24)} -> 6032 | K25: {=SUM(K6:K24)} -> 0 | L25: {=SUM(L6:L24)} -> 4570 | M25: {=SUM(M6:M24)} -> 14000.42 | N25: {=SUM(N6:N24)} -> 75000 | O25: {=SUM(O6:O24)} -> 3596.68 | P25: {=SUM(P6:P24)} -> 575.44 | Q25: {=SUM(Q6:Q24)} -> 0 | ... W25: {=SUM(W6:W24)} -> 0 | X25: {=W25+V25+U25+T25+S25+R25+Q25+P25+O25+N25+M25+L25+K25+J25+I25+H25} -> 105174.54
D27: Concepto CTA 1385 AFIRME | E27: BANCOS | G27: BANCOS
B28: Fecha | E28: NOTARIA | G28: CHEQUES
C29: INGRESO
B30: 45698 | C30: ABASTECEDORA DE OFNA | D30: PAPELERIA | G30: 1616.71 | Q30: 1616.71
B31: 45698 | C31: ABASTECEDORA DE OFNA | D31: PAPELERIA | G31: 1616.71 | Q31: 1616.71
B32: 45702 | C32: NOSOTROS MISMOS | D32: PAGO DE QUINCENA | G32: 14002.08 | M32: {=G32} -> 14002.08
B33: 45705 | C33: AFIRME | D33: COMISION | G33: 10 | O33: 10
B34: 45705 | C34: AFIRME | D34: IVA | G34: 1.6 | P34: 1.6
B35: 45705 | C35: AFIRME | D35: COMISION VTA TPVCR 9346260 | G35: 715.38 | O35: 715.38
B36: 45705 | C36: AFIRME | D36: IVA COMISION VTA TPVCR 9346260 | G36: 114.46 | P36: 114.46
B37: 45705 | C37: AFIRME | D37: COMISION VTA TPVCR 9346260 | G37: 2147.75 | O37: 2147.75
B38: 45705 | C38: AFIRME | D38: IVA COMISION VTA TPVCR 9346260 | G38: 343.64 | P38: 343.64
B39: 45705 | C39: AFIRME | D39: COMISION VTA TPVCR 9346260 | G39: 538.65 | O39: 538.65
B40: 45705 | C40: AFIRME | D40: IVA COMISION VTA TPVCR 9346260 | G40: 86.16 | P40: 86.16
B41: 45705 | C41: AFIRME | D41: COM ANUALIDAD DEL TOKEN | G41: 50 | O41: 50
...

Sheet ENERO
D1: CONSTRUYENDO LAZOS LA ESTANZUELA 2025
D3: Concepto CTA 1385 | E3: BANCOS | G3: Bancos | H3: Bancos | I3: Bancos
A4: Fecha | B4: Folio/ Cheque | C4: Tipo | E4: NOTARIA | G4: EFECTVO | H4: Cheques | I4: SALDO
B5: INGRESO | F5: TRANSFERENCIA | I5: 1069332.5
A6: 45661 | B6: 1554 | C6: ingreso | D6: APORTACION DE MIEMBROS | E6: MARIA ZENAIDA VAZQUEZ | F6: 500 | I6: {=I5+F6} -> 1069832.5
A7: 45662 | C7: ingreso | D7: APORTACION DE MIEMBROS | E7: VENTA TPVDB 09346260 | F7: 500 | I7: {=I6+F7} -> 1070332.5
A8: 45667 | C8: ingreso | D8: APORTACION DE MIEMBROS | E8: VERONICA ILEANA CARRILLO | F8: 500 | I8: {=I7+F8} -> 1070832.5
A9: 45668 | B9: 1557 | C9: ingreso | D9: APORTACION DE MIEMBROS | E9: LUCIA TAHUIL RODRIGUEZ | F9: 200 | I9: {=I8+F9} -> 1071032.5
A10: 45669 | C10: ingreso | D10: APORTACION DE MIEMBROS | E10: YOLANDA VILLEDA | G10: 500 | I10: {=I9+G10} -> 1071532.5
A11: 45674 | C11: ingreso | D11: APORTACION DE MIEMBROS | E11: MAGNOLIA VILLEDA | G11: 500 | I11: {=I10+G11} -> 1072032.5
A12: 45674 | C12: ingreso | D12: APORTACION DE MIEMBROS | E12: LETY VIDALES | G12: 5250 | I12: {=I11+G12} -> 1077282.5
A13: 45674 | B13: 1553 | C13: ingreso | D13: APORTACION DE MIEMBROS | E13: JOSÉ DE JESÚS MARRUSOU | F13: 500 | I13: {=I12+F13} -> 1077782.5
A14: 45674 | C14: ingreso | D14: APORTACION DE MIEMBROS | E14: VENTA TPVDB9346260 | F14: 107300 | I14: {=I13+F14} -> 1185082.5
A15: 45674 | C15: ingreso | D15: APORTACION DE MIEMBROS | E15: VENTA TPVDB9346260 | F15: 28450 | I15: {=I14+F15} -> 1213532.5
A16: 45674 | C16: ingreso | D16: APORTACION DE MIEMBROS | E16: VENTA TPVDB9346260 | F16: 28250 | I16: {=I15+F16} -> 1241782.5
A17: 45676 | C17: ingreso | D17: APORTACION DE MIEMBROS | E17: COMPENSACION DE SPEI | F17: 0.05 | I17: {=I16+F17} -> 1241782.6
A18: 45676 | B18: 1552 | C18: ingreso | D18: APORTACION DE MIEMBROS | E18: SAIDE LISSETTE GUERRERO A | F18: 500 | I18: {=I17+F18} -> 1242282.6
A19: 45676 | B19: 1551 | C19: ingreso | D19: APORTACION DE MIEMBROS | E19: OSCAR GONZÁLEZ ALANIS | F19: 1000 | I19: {=I18+F19} -> 1243282.6
A20: 45676 | C20: ingreso | D20: APORTACION DE MIEMBROS | E20: VENTA TPVDB9346260 | F20: 600 | I20: {=I19+F20} -> 1243882.6
A21: 45676 | C21: ingreso | D21: APORTACION DE MIEMBROS | E21: MARTHA MEZA | G21: 1000 | I21: {=I20+G21} -> 1244882.6
A22: 45676 | C22: ingreso | D22: APORTACION DE MIEMBROS | E22: MARIO LÓPEZ ALATORRE | F22: 500 | I22: {=I21+F22} -> 1245382.6
A23: 45667 | C23: ingreso | D23: APORTACION DE MIEMBROS | E23: DOLORES GUERVARA LÓPEZ Y NORA | G23: 3000 | I23: {=I22+G23} -> 1248382.6
A24: 45667 | C24: ingreso | D24: APORTACION DE MIEMBROS | E24: LUCIA TAHUIL RODRIGUEZ | F24: 200 | I24: {=I23+F24} -> 1248582.6
A25: 45671 | C25: ingreso | D25: APORTACION DE MIEMBROS | E25: DENTISTAS ESPECIALIZADOS MONTERREY | F25: 6000 | I25: {=I24+F25} -> 1254582.6
A26: 45674 | C26: egreso | D26: CONTRUYENDO LAZOS LA EST | E26: TRASPASO ENTRE CUENTAS | H26: 25000 | I26: {=I25-H26} -> 1229582.6
A27: 45674 | C27: egreso | D27: AFIRME | E27: COM VTA TPVDB9346260 | H27: 9.5 | I27: {=I26-H27} -> 1229573.1
A28: 45674 | C28: egreso | D28: AFIRME | E28: IVA DE COMISION | H28: 1.52 | I28: {=I27-H28} -> 1229571.6
A29: 45674 | C29: egreso | D29: IMSS | E29: PAGO DE IMSS | H29: 13173.14 | I29: {=I28-H29} -> 1216398.4
A30: 45674 | C30: egreso | D30: AFIRME | E30: CC NO ATENDIDO 401966 2832 | H30: 700 | I30: {=I29-H30} -> 1215698.4
A31: 45674 | C31: egreso | D31: AFIRME | E31: CC NO ATENDIDO 591707 2832 | H31: 700 | I31: {=I30-H31} -> 1214998.4
A32: 45674 | C32: egreso | D32: AFIRME | E32: VENTA TPVDB9346260 | H32: 2150.75 | I32: {=I31-H32} -> 1212847.7
A33: 45674 | C33: egreso | D33: AFIRME | E33: IVA VENTA TPVDB9346260 | H33: 344.12 | I33: {=I32-H33} -> 1212503.6
A34: 45674 | C34: egreso | D34: AFIRME | E34: VENTA TPVDB9346260 | H34: 540.55 | I34: {=I33-H34} -> 1211963
A35: 45674 | C35: egreso | D35: AFIRME | E35: IVA VENTA TPVDB9346260 | H35: 86.46 | I35: {=I34-H35} -> 1211876.6
A36: 45676 | C36: egreso | D36: AFIRME | E36: VENTA TPVDB9346260 | H36: 833.38 | I36: {=I35-H36} -> 1211043.2
A37: 45676 | C37: egreso | D37: AFIRME | E37: IVA VENTA TPVDB9346260 | H37: 133.34 | I37: {=I36-H37} -> 1210909.8
... A48: 45685 | C48: egreso | D48: AFIRME | E48: IVA DE COMISION | H48: 8 | I48: {=I47-H48} -> 1111223.9
F49: {=SUM(F6:F48)} -> 175000.05 | G49: {=SUM(G6:G48)} -> 10250 | H49: {=SUM(H26:H48)} -> 143358.7
F50: {=F49+G49} -> 185250.05
G51: CARGOS | I51: BANCO
...

Sheet FEBRERO
B2: CONSTRUYENDO LAZOS LA ESTANZUELA AC
B3: Libro de Entradas y Salidas Correspondiente al Mes de Febrero 2025
E4: Concepto CTA | F4: BANCOS | H4: Bancos | I4: Bancos | J4: Bancos
B5: Fecha | C5: Folio/ Cheque | D5: Tipo | F5: NOTARIA | H5: EFECTVO | I5: Cheques | J5: SALDO
C6: INGRESO | G6: TRANSFERENCIA | J6: 10967764
B7: 45692 | D7: ingreso | E7: APORTACION DE MIEMBROS | F7: VERÓNICA ILEANA CARRILLO ORTIZ | G7: 500
B8: 45693 | D8: ingreso | E8: APORTACION DE MIEMBROS | F8: MARTHA MEZA | G8: 500
B9: 45698 | D9: ingreso | E9: APORTACION DE MIEMBROS | F9: DEV. DE PAGO P/N0 COMP. RASTREO | G9: 1616.71
B10: 45699 | D10: ingreso | E10: APORTACION DE MIEMBROS | F10: JOSE DE JESÚS MORROSU GARZA | G10: 500
B11: 45700 | D11: ingreso | E11: APORTACION DE MIEMBROS | F11: MARIO LÓPEZ ALATORRE | G11: 500
B12: 45705 | D12: ingreso | E12: APORTACION DE MIEMBROS | F12: VTA TPVCR 9346260 | G12: 24250
B13: 45705 | D13: ingreso | E13: APORTACION DE MIEMBROS | F13: VTA TPVCR 9346260 | G13: 107150
B14: 45705 | D14: ingreso | E14: APORTACION DE MIEMBROS | F14: VTA TPVCR 9346260 | G14: 28350
B15: 45705 | D15: ingreso | E15: APORTACION DE MIEMBROS | F15: DEPOSITO DE EFECTIVO | G15: 500
B16: 45705 | D16: ingreso | E16: APORTACION DE MIEMBROS | F16: MARIA ZENAIDA | G16: 500
B17: 45705 | D17: ingreso | E17: APORTACION DE MIEMBROS | F17: VTA TPVCR 9346260 | G17: 500
B18: 45707 | D18: ingreso | E18: APORTACION DE MIEMBROS | F18: VTA TPVCR 9346260 | G18: 1000
... B21: 45707 | D21: ingreso | E21: APORTACION DE MIEMBROS | F21: VTA TPVCR 9346260 | G21: 3500
B24: 45698 | D24: egreso | E24: ABASTECEDORA DE OFNA | F24: PAPELERIA | I24: 1616.71
B25: 45698 | D25: egreso | E25: ABASTECEDORA DE OFNA | F25: PAPELERIA | I25: 1616.71
B26: 45702 | D26: egreso | E26: NOSOTROS MISMOS | F26: PAGO DE QUINCENA | I26: 14002.08
B27: 45705 | D27: egreso | E27: AFIRME | F27: COMISION | I27: 10
B28: 45705 | D28: egreso | E28: AFIRME | F28: IVA | I28: 1.6
B29: 45705 | D29: egreso | E29: AFIRME | F29: COMISION VTA TPVCR 9346260 | I29: 715.38
B30: 45705 | D30: egreso | E30: AFIRME | F30: IVA COMISION VTA TPVCR 9346260 | I30: 114.46
B31: 45705 | D31: egreso | E31: AFIRME | F31: COMISION VTA TPVCR 9346260 | I31: 2147.75
B32: 45705 | D32: egreso | E32: AFIRME | F32: IVA COMISION VTA TPVCR 9346260 | I32: 343.64
B33: 45705 | D33: egreso | E33: AFIRME | F33: COMISION VTA TPVCR 9346260 | I33: 538.65
B34: 45705 | D34: egreso | E34: AFIRME | F34: IVA COMISION VTA TPVCR 9346260 | I34: 86.16
B35: 45705 | D35: egreso | E35: AFIRME | F35: COM ANUALIDAD DEL TOKEN | I35: 50
... B49: 45716 | D49: egreso | E49: IVA DE COMISION | F49: IVA DE COMISION | I49: 64
G52: {=SUM(G7:G51)} -> 172416.71 | H52: {=SUM(H7:H51)} -> 0 | I52: {=SUM(I24:I51)} -> 73375.72
G53: {=G52+H52} -> 172416.71
H54: CARGOS | J54: BANCO
E55: SIN RECIBO C AFI | F55: {=500+500+500+500+750+1000+1000+500+500+1000} -> 6750 | H55: AF. TD, TC | I55: {=G16+G17} -> 1000 | J55: 56700
E56: CAR TIMBRADO | F56: 64700 | H56: AF. AMEX | I56: 14750 | J56: 107300
E57: TRANF. DIRECTO PARA T | F57: {=G7+G10+G14+G19+G20+G23+G25+G26} -> 32400 | H57: P. TD,AMEX | I57: 81050
E58: TRANF S/T DIR | F58: {=G8+G9+G18+G21} -> 6616.71 | H58: P. AMEX | I58: 11500
E59: EFECTIVO | F59: {=H52} -> 0
E60: P. TIMBRAR TRANS | F60: {=I57+I58} -> 92550 | I60: {=I58+I57+I56+I55} -> 108300 | J60: {=J56+J55} -> 164000
...

Sheet MARZO
B2: CONSTRUYENDO LAZOS LA ESTANZUELA AC
B3: Libro de Entradas y Salidas Correspondiente al Mes de MARZO 2025
E4: Concepto CTA | F4: BANCOS | H4: Bancos | I4: Bancos | J4: Bancos
B5: Fecha | C5: Folio/ Cheque | D5: Tipo | F5: NOTARIA | H5: EFECTVO | I5: Cheques | J5: SALDO
C6: INGRESO | G6: TRANSFERENCIA | J6: 1195817.9
B7: 45720 | C7: F-1707 | D7: ingreso | E7: APORTACION DE MIEMBROS | F7: LUCIA TAHUIL RODRIGUEZ | G7: 200 | J7: {=J6+G7} -> 1196017.9
B8: 45720 | D8: ingreso | E8: APORTACION DE MIEMBROS | F8: LOLIS GUEVARA | G8: 1500 | J8: {=J7+G8} -> 1197517.9
B9: 45721 | D9: ingreso | E9: APORTACION DE MIEMBROS | F9: DEPOSITO EFECTIVO | G9: 500 | J9: {=J8+G9} -> 1198017.9
B10: 45726 | C10: 1704 | D10: ingreso | E10: APORTACION DE MIEMBROS | F10: ANTONIO MORALES (CASA DE LA ABUELA) | G10: 3000 | J10: {=J9+G10} -> 1201017.9
B11: 45726 | C11: 1705 | D11: ingreso | E11: APORTACION DE MIEMBROS | F11: MARIA DEL CARMEN (CASA DE LA ABUELA) | G11: 3000 | J11: {=J10+G11} -> 1204017.9
B12: 45727 | C12: 1706 | D12: ingreso | E12: APORTACION DE MIEMBROS | F12: JOSÉ RAFAEL GUTIERREZ RANGEL | G12: 500 | J12: {=J11+G12} -> 1204517.9
B13: 45727 | D13: ingreso | E13: APORTACION DE MIEMBROS | F13: MA. DEL SOCORRO CONTRERAS | G13: 500 | J13: {=J12+G13} -> 1205017.9
B14: 45727 | D14: ingreso | E14: APORTACION DE MIEMBROS | F14: NORA GALVAN | G14: 1000 | J14: {=J13+G14} -> 1206017.9
B15: 45727 | D15: ingreso | E15: APORTACION DE MIEMBROS | F15: EVY SALAZAR | G15: 1000 | J15: {=J14+G15} -> 1207017.9
B16: 45727 | D16: ingreso | E16: APORTACION DE MIEMBROS | F16: MA. ROSA Y MANUEL | G16: 4500 | J16: {=J15+G16} -> 1211517.9
B17: 45734 | C17: 1819 | D17: ingreso | E17: APORTACION DE MIEMBROS | F17: VERONICA ILEANA CARRILLO ORTIZ | G17: 500 | J17: {=J16+G17} -> 1212017.9
B18: 45734 | D18: ingreso | E18: AFIRME | F18: VENTA TPVCR AMX 09346260 | G18: 22550 | J18: {=J17+G18} -> 1234567.9
B19: 45734 | D19: ingreso | E19: AFIRME | F19: VENTA TPVCR AMX 09346260 | G19: 105650 | J19: {=J18+G19} -> 1340217.9
B20: 45734 | D20: ingreso | E20: AFIRME | F20: VENTA TPVCR AMX 09346260 | G20: 26650 | J20: {=J19+G20} -> 1366867.9
B21: 45734 | C21: 1710 | D21: ingreso | E21: APORTACION DE MIEMBROS | F21: MARIO ALATORRE LÓPEZ | G21: 500 | J21: {=J20+G21} -> 1367367.9
B22: 45734 | C22: 1709 | D22: ingreso | E22: APORTACION DE MIEMBROS | F22: JOSÉ DE JESÚS MARRUSOU GARZA | G22: 500 | J22: {=J21+G22} -> 1367867.9
B23: 45734 | D23: ingreso | E23: APORTACION DE MIEMBROS | F23: LUIS FERNANDO MARTINEZ DOMINGUEZ | G23: 500 | J23: {=J22+G23} -> 1368367.9
B24: 45735 | C24: 1713 | D24: ingreso | E24: ANTONIO MORALES | F24: VENTA TPVCR AMX 09346260 | G24: 1500 | J24: {=J23+G24} -> 1369867.9
B25: 45735 | C25: 1714 | D25: ingreso | E25: CARMEN OCHOA | F25: VENTA TPVCR AMX 09346260 | G25: 1500 | J25: {=J24+G25} -> 1371367.9
B26: 45735 | D26: ingreso | E26: AFIRME | F26: VENTA TPVCR AMX 09346260 | G26: 1500 | J26: {=J25+G26} -> 1372867.9
B27: 45736 | D27: ingreso | E27: AFIRME | F27: VENTA TPVCR AMX 09346260 | G27: 1250 | J27: {=J26+G27} -> 1374117.9
B28: 45736 | D28: ingreso | E28: AFIRME | F28: VENTA TPVCR AMX 09346260 | G28: 500 | J28: {=J27+G28} -> 1374617.9
B29: 45736 | C29: 1712 | D29: ingreso | E29: APORTACION DE MIEMBROS | F29: OSCAR ALANIS | G29: 1000 | J29: {=J28+G29} -> 1375617.9
B30: 45737 | C30: 1711 | D30: ingreso | E30: APORTACION DE MIEMBROS | F30: MARIA ZENIDA VAZQUEZ ALVAREZ | G30: 1000 | J30: {=J29+G30} -> 1376617.9
B31: 45740 | D31: ingreso | E31: AFIRME | F31: VENTA TPVCR AMX 09346260 | G31: 500 | J31: {=J30+G31} -> 1377117.9
B34: 45719 | D34: egreso | E34: CONSTRUYENDO LAZOS | F34: TRASPASO ENTRE CUENTAS | I34: 35000 | J34: {=J31-I34} -> 1342117.9
B35: 45719 | D35: egreso | E35: CONSTRUYENDO LAZOS | F35: TRASPASO ENTRE CUENTAS | I35: 30000 | J35: {=J34-I35} -> 1312117.9
B36: 45720 | D36: egreso | E36: EVENTOS NC | F36: DESAYUNO DE CAMPAÑA | I36: 93960 | J36: {=J35-I36} -> 1218157.9
B37: 45723 | D37: egreso | E37: CONSTUYENDO LAZOS | F37: TRASPASO ENTRE CUENTAS | I37: 29000 | J37: {=J36-I37} -> 1189157.9
B38: 45723 | D38: egreso | E38: AFIRME | F38: MTTO ANUAL SERVICIO | I38: 500 | J38: {=J37-I38} -> 1188657.9
B39: 45723 | D39: egreso | E39: AFIRME | F39: IVA DE COMISION | I39: 80 | J39: {=J38-I39} -> 1188577.9
B40: 45727 | D40: egreso | E40: SAT | F40: IMPUESTOS MES FEBRERO ISR | I40: 3670 | J40: {=J39-I40} -> 1184907.9
B41: 45727 | D41: egreso | E41: SAT | F41: IMPUESTO RET | I41: 1100 | J41: {=J40-I41} -> 1183807.9
B42: 45727 | D42: egreso | E42: IMSS | F42: PAGO DE IMSS | I42: 13272.32 | J42: {=J41-I42} -> 1170535.6
B43: 45727 | D43: egreso | E43: JBC DESPACHO DE CONTADORES | F43: HONORARIOS DE MAQUILA C | I43: 4640 | J43: {=J42-I43} -> 1165895.6
...

Sheet ABRIL
B2: CONSTRUYENDO LAZOS LA ESTANZUELA AC
B3: Libro de Entradas y Salidas Correspondiente al Mes de Abril 2025
E4: Concepto CTA | F4: BANCOS | H4: Bancos | I4: Bancos | J4: Bancos
B5: Fecha | C5: Folio/ Cheque | D5: Tipo | E5: 12061001385 | F5: NOTARIA | H5: EFECTVO | I5: Cheques | J5: SALDO
C6: INGRESO | G6: TRANSFERENCIA | J6: {=1131337.74-500} -> 1130837.7
B7: 45748 | D7: ingreso | E7: APORTACION DE MIEMBROS | F7: FLOR CARCAÑO | G7: 0 | H7: 500 | J7: {=J6+H7} -> 1131337.7
B8: 45748 | D8: ingreso | E8: APORTACION DE MIEMBROS | F8: LUPITA GUEVARA | G8: 0 | H8: 1500 | J8: {=J7+H8} -> 1132837.7
B9: 45754 | D9: ingreso | E9: APORTACION DE MIEMBROS | F9: SOCORRO CONTRERAS | G9: 0 | H9: 500 | J9: {=J8+H9} -> 1133337.7
B10: 45751 | D10: ingreso | E10: APORTACION DE MIEMBROS | F10: MARTHA VILLEDA | G10: 0 | H10: 250 | J10: {=J9+H10} -> 1133587.7
B11: 45751 | D11: ingreso | E11: APORTACION DE MIEMBROS | F11: SOCORRO CONTRERAS | G11: 0 | H11: 500 | J11: {=J10+H11} -> 1134087.7
B12: 45763 | C12: F.1838 | D12: ingreso | E12: APORTACION DE MIEMBROS | F12: MARIA DEL CARMEN OCHOA LEAL | G12: 1500 | J12: {=J11+G12} -> 1135587.7
B13: 45762 | D13: ingreso | E13: AFIRME | F13: VENTA TPVCR AMX 09346260 | G13: 21550 | J13: {=J12+G13} -> 1157137.7
B14: 45762 | D14: ingreso | E14: AFIRME | F14: VENTA TPVCR AMX 09346260 | G14: 46800 | J14: {=J13+G14} -> 1203937.7
B15: 45763 | D15: ingreso | E15: APORTACION DE MIEMBROS | F15: VENTA TPVCR AMX 09346260 | G15: 7800 | J15: {=J14+G15} -> 1211737.7
B16: 45763 | C16: F.1836 | D16: ingreso | E16: APORTACION DE MIEMBROS | F16: JOSE DE JESUS MARROSU GARZA | G16: 500 | J16: {=J15+G16} -> 1212237.7
B17: 45763 | C17: F. 1837 | D17: ingreso | E17: APORTACION DE MIEMBROS | F17: ANTONIO MORALES RANGEL | G17: 1500 | J17: {=J16+G17} -> 1213737.7
B18: 45763 | C18: F.1835 | D18: ingreso | E18: APORTACION DE MIEMBROS | F18: OSCAR GONZALEZ ALANIS | G18: 1000 | J18: {=J17+G18} -> 1214737.7
B19: 45763 | C19: F.1840 | D19: ingreso | E19: APORTACION DE MIEMBROS | F19: MARIO A LA TORRE | G19: 500 | J19: {=J18+G19} -> 1215237.7
B20: 45768 | C20: F. 1839 | D20: ingreso | E20: APORTACION DE MIEMBROS | F20: W CONSLTING ING | G20: 500 | J20: {=J19+G20} -> 1215737.7
B21: 45776 | C21: F. 1956 | D21: ingreso | E21: APORTACION DE MIEMBROS | F21: VERONICA ILEANA CARRILLO | G21: 300 | J21: {=J20+G21} -> 1216037.7
B22: 45777 | C22: F. 1952 | D22: ingreso | E22: APORTACION DE MIEMBROS | F22: VERONICA ILEANA CARRILLO | G22: 200 | J22: {=J21+G22} -> 1216237.7
B24: 45754 | D24: egreso | E24: CONSTRUYENDO LAZOS | F24: TRASPASO ENTRE CUENTAS | I24: 100000 | J24: {=J22-I24} -> 1116237.7
B25: 45754 | D25: egreso | E25: LABORATORIO Y ENSAYE SA | F25: TRASPASO ENTRE CUENTAS | I25: 47850 | J25: {=J24-I25} -> 1068387.7
B26: 45754 | D26: egreso | E26: RAUL SANCHEZ QUISTIAN | F26: ANTICIPO DE SONIDO DE TOLDO PARROQUIA | I26: 27448.2 | J26: {=J25-I26} -> 1040939.5
B27: 45755 | D27: egreso | E27: EVENTOS NC | F27: DESAYUNO DE CAMPAÑA | I27: 120000 | J27: {=J26-I27} -> 920939.54
B28: 45756 | D28: egreso | E28: RAUL SANCHEZ QUISTIAN | F28: PAGO TOT. DE SONIDO DE TOLDO PARROQUIA | I28: 27448.2 | J28: {=J27-I28} -> 893491.34
B29: 45756 | D29: egreso | E29: NOSOTROS MISMOS | F29: DISPERCIÓN DE FONDOS | I29: 14002.08 | J29: {=J28-I29} -> 879489.26
B30: 45761 | D30: egreso | E30: AFIRME | F30: COMISION POR DISPERSION DE FONDOS | I30: 10 | J30: {=J29-I30} -> 879479.26
B31: 45761 | D31: egreso | E31: AFIRME | F31: IVA POR COMISION DISPERSIÓN | I31: 1.6 | J31: {=J30-I31} -> 879477.66
B32: 45763 | D32: egreso | E32: AFIRME | F32: COMVTA TPVCR AMX 09346260 | I32: 101.72 | J32: {=J31-I32} -> 879375.94
B33: 45763 | D33: egreso | E33: AFIRME | F33: IVA DE COMVTA TPVCR 09346260 | I33: 635.73 | J33: {=J32-I33} -> 878740.21
B34: 45763 | D34: egreso | E34: AFIRME | F34: COMVTA TPVCR AMX 09346260 | I34: 936 | J34: {=J33-I34} -> 877804.21
B35: 45763 | D35: egreso | E35: AFIRME | F35: IVA DE COMVTA TPVCR 09346260 | I35: 149.76 | J35: {=J34-I35} -> 877654.45
B36: 45763 | D36: egreso | E36: AFIRME | F36: VENTA TPVCR 0946260 | I36: 148.2 | J36: {=J35-I36} -> 877506.25
... B43: 45776 | D43: egreso | E43: AFIRME | F43: IVA DE COMISION DE DISPERSION | I43: 1.6 | J43: {=J42-I43} -> 862581.76
I44: 0 | J44: {=J43-I44} -> 862581.76
I45: 0 | J45: {=J44-I45} -> 862581.76
I46: 0 | J46: {=J45-I46} -> 862581.76
I47: 0 | J47: {=J46-I47} -> 862581.76
G49: {=SUM(G7:G47)} -> 82150 | H49: {=SUM(H7:H47)} -> 3250 | I49: {=SUM(I24:I47)} -> 353655.98
...

Sheet MAYO
B2: CONSTRUYENDO LAZOS LA ESTANZUELA AC
B3: Libro de Entradas y Salidas Correspondiente al Mes de MAYO 2025
E4: Concepto CTA | F4: BANCOS | H4: Bancos | I4: Bancos | J4: Bancos
B5: Fecha | C5: Folio/ Cheque | D5: Tipo | E5: 12061001385 | F5: NOTARIA | H5: EFECTVO | I5: Cheques | J5: SALDO
C6: INGRESO | G6: TRANSFERENCIA | J6: 861247.76
B7: 45779 | C7: F. 2074 | D7: ingreso | E7: APORTACION DE MIEMBROS | F7: MARIA ZENAIDA VAZQUEZ ALVAREZ | G7: 500 | J7: {=J6+G7} -> 861747.76
B8: 45779 | D8: ingreso | E8: APORTACION DE MIEMBROS | F8: MARTHA MEZA | H8: 500 | J8: {=J7+H8} -> 862247.76
B9: 45782 | C9: F. 2073 | D9: ingreso | E9: APORTACION DE MIEMBROS | F9: INES CHI | G9: 500 | J9: {=J8+G9} -> 862747.76
B10: 45782 | D10: ingreso | E10: APORTACION DE MIEMBROS | F10: SOCORRO CONTRERAS | H10: 500 | J10: {=J9+H10} -> 863247.76
B11: 45782 | D11: ingreso | E11: APORTACION DE MIEMBROS | F11: DOLORES LOPEZ | H11: 1500 | J11: {=J10+H11} -> 864747.76
B12: 45790 | D12: ingreso | E12: APORTACION DE MIEMBROS | F12: FLORINDA CARCAÑO | H12: 500 | J12: {=J11+H12} -> 865247.76
B13: 45790 | D13: ingreso | E13: APORTACION DE MIEMBROS | F13: MARTAH MEZA | H13: 500 | J13: {=J12+H13} -> 865747.76
B14: 45792 | D14: ingreso | E14: AFIRME | F14: VTA TPVDB 9346260 | G14: 43250 | J14: {=J13+G14} -> 908997.76
B15: 45792 | D15: ingreso | E15: AFIRME | F15: VTA TPVDB 9346260 | G15: 7300 | J15: {=J14+G15} -> 916297.76
B16: 45792 | D16: ingreso | E16: AFIRME | F16: VTA TPVDB 9346260 | G16: 22050 | J16: {=J15+G16} -> 938347.76
B17: 45792 | C17: F. 1965 | D17: ingreso | E17: APORTACION DE MIEMBROS | F17: OSCAR GONZÁLEZ ALANIS | G17: 1000 | J17: {=J16+G17} -> 939347.76
B18: 45792 | C18: F. 1964 | D18: ingreso | E18: APORTACION DE MIEMBROS | F18: MARIO LOPEZ ALATORRE | G18: 500 | J18: {=J17+G18} -> 939847.76
B19: 45793 | C19: F.1962 | D19: ingreso | E19: APORTACION DE MIEMBROS | F19: ANTONIO MORALES | G19: 1500 | J19: {=J18+G19} -> 941347.76
B20: 45793 | C20: F. 1961 | D20: ingreso | E20: APORTACION DE MIEMBROS | F20: MA. DEL CARMEN OCHOA | G20: 1500 | J20: {=J19+G20} -> 942847.76
B21: 45796 | D21: ingreso | E21: APORTACION DE MIEMBROS | F21: MARTHA VILLEDA | H21: 500 | J21: {=J20+H21} -> 943347.76
B22: 45797 | D22: ingreso | E22: APORTACION DE MIEMBROS | F22: F. 1966 $ 1250.00+ F. 1967 $ 500.00 | G22: 1750 | J22: {=J21+G22} -> 945097.76
B26: 45782 | D26: egreso | E26: DORA ALICIA RESENDIZ LOZANO | F26: LAMBRIN PARA OFICINA | I26: 16768.96 | J26: {=J22-I26} -> 928328.8
B27: 45789 | D27: egreso | E27: DORA ALICIA RESENDIZ LOZANO | F27: LAMBRIN PARA OFICINA | I27: 7888.99 | J27: {=J26-I27} -> 920439.81
B28: 45790 | D28: egreso | E28: NOSOTROS MISMOS | F28: DISPESION DE NOMINA | I28: 14002.08 | J28: {=J27-I28} -> 906437.73
B29: 45790 | D29: egreso | E29: AFIRME | F29: COMISION POR DISOPERCION | I29: 10 | J29: {=J28-I29} -> 906427.73
B30: 45790 | D30: egreso | E30: AFIRME | F30: IVA DE DISPERSIÓN | I30: 1.6 | J30: {=J29-I30} -> 906426.13
B31: 45792 | D31: egreso | E31: AFIRME | F31: COM VTA TPVDB 9346260 | I31: 865 | J31: {=J30-I31} -> 905561.13
B32: 45792 | D32: egreso | E32: AFIRME | F32: IVA VTA TPVDB 9346260 | I32: 138.4 | J32: {=J31-I32} -> 905422.73
B33: 45792 | D33: egreso | E33: AFIRME | F33: COM VTA TPVDB 9346260 | I33: 138.7 | J33: {=J32-I33} -> 905284.03
B34: 45792 | D34: egreso | E34: AFIRME | F34: IVA VTA TPVDB 9346260 | I34: 22.18 | J34: {=J33-I34} -> 905261.85
B35: 45792 | D35: egreso | E35: AFIRME | F35: COM VTA TPVDB 9346260 | I35: 650.48 | J35: {=J34-I35} -> 904611.37
B36: 45792 | D36: egreso | E36: AFIRME | F36: IVA VTA TPVDB 9346260 | I36: 104.08 | J36: {=J35-I36} -> 904507.29
B37: 45797 | D37: egreso | E37: AFIRME | F37: COM VTA TPVDB 9346260 | I37: 35 | J37: {=J36-I37} -> 904472.29
B38: 45797 | D38: egreso | E38: AFIRME | F38: IVA VTA TPVDB 9346260 | I38: 5.6 | J38: {=J37-I38} -> 904466.69
... B42: 45807 | D42: egreso | E42: AFIRME | F42: IVA VTA TPVDB 9346260 | I42: 1.6 | J42: {=J41-I42} -> 876779.86
H44: 0
G45: {=SUM(G7:G44)} -> 79850 | H45: {=SUM(H7:H44)} -> 4000 | I45: {=SUM(I24:I44)} -> 68317.9
G46: {=G45+H45} -> 83850
H47: CARGOS | J47: BANCO
E48: SIN RECIBO C AFI | F48: 4450 | G48: F. 2075 | H48: AF. TD, TC | I48: 0 | J48: 0
...

Sheet JUNIO
B2: CONSTRUYENDO LAZOS LA ESTANZUELA AC
B3: Libro de Entradas y Salidas Correspondiente al Mes de JUNIO 2025
E4: Concepto CTA | F4: BANCOS | H4: Bancos | I4: Bancos | J4: Bancos
B5: Fecha | C5: Folio/ Cheque | D5: Tipo | E5: 12061001385 | F5: NOTARIA | H5: EFECTVO | I5: Cheques | J5: SALDO
C6: INGRESO | G6: TRANSFERENCIA | J6: {=829465.86-500} -> 828965.86
B7: 45810 | C7: 2082 | D7: ingreso | E7: APORTACION DE MIEMBROS | F7: ZENAIDA VAZQUEZ ALVAREZ | G7: 500 | J7: {=J6+G7} -> 829465.86
B8: 45812 | D8: ingreso | E8: APORTACION DE MIEMBROS | F8: GEORGINA Y MANUEL MARTINEZ | H8: 500 | J8: {=J7+H8} -> 829965.86
B9: 45813 | D9: ingreso | E9: ABASTECEDORA DE OFICINA | F9: DEV DE SPEI | G9: 3309.25 | J9: {=J8+G9} -> 833275.11
B10: 45818 | D10: ingreso | E10: APORTACION DE MIEMBROS | F10: LUPITA GUEVARA Y REYNA ESQUIVEL | H10: 1000 | J10: {=J9+H10} -> 834275.11
B11: 45824 | D11: ingreso | E11: AFIRME | F11: VTA TPVCR AMX 09346260 | G11: 21050 | J11: {=J10+H11} -> 834275.11
B12: 45824 | D12: ingreso | E12: AFIRME | F12: VTA TPVCR AMX 09346260 | G12: 45500 | J12: {=J11+H12} -> 834275.11
B13: 45824 | D13: ingreso | E13: AFIRME | F13: VTA TPVDB 09346260 | G13: 6500 | J13: {=J12+H13} -> 834275.11
B14: 45824 | C14: 2194 | D14: ingreso | E14: APORTACION DE MIEMBROS | F14: OSCAR GONZALEZ ALANIS | G14: 1000 | J14: {=J13+G14} -> 835275.11
B15: 45824 | C15: 2195 | D15: ingreso | E15: APORTACION DE MIEMBROS | F15: MARIO LOPEZ A LA TORRE | G15: 500 | J15: {=J14+G15} -> 835775.11
B16: 45824 | C16: 2196 | D16: ingreso | E16: APORTACION DE MIEMBROS | F16: INES CHI SANTANDER | G16: 500 | J16: {=J15+G16} -> 836275.11
B17: 45826 | D17: ingreso | E17: APORTACION DE MIEMBROS | F17: MERCEDES YADIRA VILLAFRANCO | H17: 500 | J17: {=J16+G17} -> 836275.11
B18: 45826 | D18: ingreso | E18: APORTACION DE MIEMBROS | F18: SOCORRO CONTRERAS | H18: 500 | J18: {=J17+G18} -> 836275.11
B19: 45826 | D19: ingreso | E19: APORTACION DE MIEMBROS | F19: LAURA MENDIETA | H19: 200 | J19: {=J18+G19} -> 836275.11
B20: 45827 | D20: ingreso | E20: AFIRME | F20: VTA TPVCR AMX 09346260 BAN | G20: 1000 | J20: {=J19+G20} -> 837275.11
B21: 45827 | D21: ingreso | E21: AFIRME | F21: VTA. TPVCR AMX 0934620 BAN | G21: 18350 | J21: {=J20+H21} -> 837275.11
B22: 45827 | D22: ingreso | E22: AFIRME | F22: VTA. TPBVCR AMX 09345260 BAN | G22: 52700 | J22: {=J21+G22} -> 889975.11
B23: 45831 | D23: ingreso | E23: AFIRME | F23: VTA. TPVCR AMX 09346260 | G23: 500 | J23: {=J22+G23} -> 890475.11
B24: 45831 | D24: ingreso | E24: AFIRME | F24: VTA. TPVCR AMX 09346260 | G24: 2400 | J24: {=J23+G24} -> 892875.11
B25: 45831 | D25: ingreso | E25: AFIRME | F25: VTA. TPVCR AMX 09346260 | G25: 1500 | J25: {=J24+G25} -> 894375.11
B26: 45832 | D26: ingreso | E26: APORTACION DE MIEMBROS | F26: DEP. EN EFECTIVO | H26: 500 | J26: {=J25+G26} -> 894375.11
B27: 45834 | C27: 2200 | D27: ingreso | E27: APORTACION DE MIEMBROS | F27: MA. DEL CARMEN OCHOA LEAL | G27: 1500 | J27: {=J26+G27} -> 895875.11
B28: 45834 | C28: 2201 | D28: ingreso | E28: APORTACION DE MIEMBROS | F28: ANTONIO MORALES RANGEL | G28: 1500 | J28: {=J27+G28} -> 897375.11
B29: 45838 | C29: 2216 | D29: ingreso | E29: APORTACION DE MIEMBROS | F29: VERONICA ILEANA CARRILLO ORTIZ | G29: 500 | J29: {=J28+G29} -> 897875.11
J30: {=J29+G30} -> 897875.11
B34: 45813 | D34: egreso | E34: ABASTECEDORA DE OFINA SA DE CV | F34: PAPELERIA | I34: 3309.25 | J34: {=J29-I34} -> 894565.86
B35: 45813 | D35: egreso | E35: ABASTECEDORA DE OFINA SA DE CV | F35: PAPELERIA | I35: 3309.25 | J35: {=J34-I35} -> 891256.61
B36: 45821 | D36: egreso | E36: AFIRME | F36: DISPERSION DE FONDOS | I36: 14002.08
B37: 45821 | D37: egreso | E37: AFIRME | F37: COMISION DISPERSION DE FONDOS | I37: 10 | J37: {=J35-I37} -> 891246.61
B38: 45821 | D38: egreso | E38: AFIRME | F38: IVA COM. CARGO ANTERIOR | I38: 1.6 | J38: {=J37-I38} -> 891245.01
B39: 45824 | D39: egreso | E39: AFIRME | F39: COMVTA TPVCR AMX 09346260 | I39: 620.98 | J39: {=J38-I39} -> 890624.03
B40: 45824 | D40: egreso | E40: AFIRME | F40: IVA COMVTA TPVCR AMX 09346260 | I40: 99.36 | J40: {=J39-I40} -> 890524.67
B41: 45824 | D41: egreso | E41: AFIRME | F41: COMVTA TPVCR 09346260 | I41: 910 | J41: {=J40-I41} -> 889614.67
B42: 45824 | D42: egreso | E42: AFIRME | F42: IVA COMVTA TPVCR 09346260 | I42: 145.6 | J42: {=J41-I42} -> 889469.07
B43: 45824 | D43: egreso | E43: AFIRME | F43: COMVTA TPVDB 09346260 | I43: 123.5 | J43: {=J42-I43} -> 889345.57
B44: 45824 | D44: egreso | E44: AFIRME | F44: IVA COMVTA TPVDB 09346260 | I44: 19.75 | J44: {=J43-I44} -> 889325.82
...

Sheet JULIO
B2: CONSTRUYENDO LAZOS LA ESTANZUELA AC
B3: Libro de Entradas y Salidas Correspondiente al Mes de JULIO 2025
E4: Concepto CTA | F4: BANCOS | H4: Bancos | I4: Bancos | J4: Bancos
B5: Fecha | C5: Folio/ Cheque | D5: Tipo | E5: 12061001385 | F5: NOTARIA | H5: EFECTVO | I5: Cheques | J5: SALDO
C6: INGRESO | G6: TRANSFERENCIA | J6: 951414.13
B7: 45839 | D7: ingreso | E7: APORTACION DE MIEMBROS | F7: JOSE LUIS GONZALEZ | H7: 500 | J7: {=J6+G7} -> 951414.13
B8: 45841 | C8: 2224 | D8: ingreso | E8: APORTACION DE MIEMBROS | F8: MARIA ZENAIDA VAZQUEZ ALVAREZ | G8: 500 | J8: {=J7+H8} -> 951414.13
B9: 45845 | C9: 2226 | D9: ingreso | E9: APORTACION DE MIEMBROS | F9: JOSE DE JESUS MARROSU GARZA | G9: 1000 | J9: {=J8+G9} -> 952414.13
B10: 45846 | D10: ingreso | E10: APORTACION DE MIEMBROS | F10: DOLORES LOPEZ GUEVARA | H10: 2000 | J10: {=J9+H10} -> 954414.13
B11: 45846 | D11: ingreso | E11: APORTACION DE MIEMBROS | F11: JOSE LUIS GONZALEZ | H11: 250 | J11: {=J10+H11} -> 954664.13
B12: 45853 | D12: ingreso | E12: AFIRME | F12: VENTA TPVCR 09346260 | G12: 50700 | J12: {=J11+H12} -> 954664.13
B13: 45853 | D13: ingreso | E13: AFIRME | F13: VENTA TPVDB 09346260 | G13: 7700 | J13: {=J12+H13} -> 954664.13
B14: 45853 | D14: ingreso | E14: AFIRME | F14: VENTA TPVCR AMX 09346260 | G14: 20550 | J14: {=J13+G14} -> 975214.13
B15: 45853 | D15: ingreso | E15: AFIRME | F15: SPEI DEV. EXCEDE EL LIMITE DE SALDO | G15: 92800 | J15: {=J14+G15} -> 1068014.1
B16: 45853 | D16: ingreso | E16: APORTACION DE MIEMBROS | F16: FLORINDA CARCAÑO | H16: 1500 | J16: {=J15+G16} -> 1068014.1
B17: 45853 | D17: ingreso | E17: APORTACION DE MIEMBROS | F17: SOCORRO CONTRERAS | H17: 500 | J17: {=J16+G17} -> 1068014.1
B18: 45855 | D18: ingreso | E18: AFIRME | F18: VENTA TPVCR 09346260 | G18: 1200 | J18: {=J17+G18} -> 1069214.1
B19: 45855 | C19: 2335 | D19: ingreso | E19: APORTACION DE MIEMBROS | F19: MARIO LOPEZ ALATORRE | G19: 500 | J19: {=J18+G19} -> 1069714.1
B20: 45856 | C20: 2334 | D20: ingreso | E20: APORTACION DE MIEMBROS | F20: INES CHI SANTANDER | G20: 500 | J20: {=J19+G20} -> 1070214.1
B21: 45856 | C21: 2333 | D21: ingreso | E21: APORTACION DE MIEMBROS | F21: MA. DEL CARMEN OCHOA | G21: 1500 | J21: {=J20+H21} -> 1070214.1
B22: 45856 | C22: 2332 | D22: ingreso | E22: APORTACION DE MIEMBROS | F22: ANTONIO MORALES | G22: 1500 | J22: {=J21+G22} -> 1071714.1
J23: {=J22+G23} -> 1071714.1
J24: {=J23+G24} -> 1071714.1
J25: {=J24+G25} -> 1071714.1
B26: 45856 | D26: ingreso | E26: APORTACION DE MIEMBROS | G26: {=SUM(G7:G25)} -> 178450 | J26: {=J25+G26} -> 1250164.1
B27: 45856 | D27: ingreso | E27: APORTACION DE MIEMBROS | H27: {=SUM(H7:H26)} -> 4750 | J27: {=J26+G27} -> 1250164.1
J28: {=J27+G28} -> 1250164.1
J29: {=J28+G29} -> 1250164.1
J30: {=J29+G30} -> 1250164.1
B34: 45849 | D34: egreso | E34: BANORTE | F34: TRASPASO ENTRE CUENTAS | I34: 100000 | J34: {=J29-I34} -> 1150164.1
B35: 45852 | D35: egreso | E35: NOSOTROS MISMOS | F35: DISPERSION DE NOMINA | I35: 13068.7 | J35: {=J34-I35} -> 1137095.4
B36: 45852 | D36: egreso | E36: AFIRME | F36: COM. E IVA DISPERSION DE FONDOS | I36: 11.6 | J36: {=J35-I36} -> 1137083.8
B37: 45853 | D37: egreso | E37: AFIRME | F37: COMVTA TPVCR 09346260 | I37: 1014 | J37: {=J36-I37} -> 1136069.8
B38: 45853 | D38: egreso | E38: AFIRME | F38: IVA COMVTA TPVCR 09346260 | I38: 162.24 | J38: {=J37-I38} -> 1135907.6
B39: 45853 | D39: egreso | E39: AFIRME | F39: COMVTA TPVDB 09346260 | I39: 146.3 | J39: {=J38-I39} -> 1135761.3
B40: 45853 | D40: egreso | E40: AFIRME | F40: IVA COMVTA TPVDB 09346260 | I40: 23.4 | J40: {=J39-I40} -> 1135737.9
B41: 45853 | D41: egreso | E41: AFIRME | F41: COMVTA TPVCR AMX 096346260 | I41: 606.23 | J41: {=J40-I41} -> 1135131.7
B42: 45853 | D42: egreso | E42: AFIRME | F42: IVA COMVTA TPVCR AMX 096346260 | I42: 97 | J42: {=J41-I42} -> 1135034.7
B43: 45853 | D43: egreso | E43: JORGE DANIEL MEDELLIN L. | F43: PAGO DE SERVICIO DE ESCOMBRO | I43: 92800 | J43: {=J42-I43} -> 1042234.7
B44: 45854 | D44: egreso | E44: NOSOTROS MISMOS | F44: DISPERSION DE NOMINA | I44: 432.49 | J44: {=J43-I44} -> 1041802.2
...

Sheet AGOSTO
B2: CONSTRUYENDO LAZOS LA ESTANZUELA AC
B3: Libro de Entradas y Salidas Correspondiente al Mes de AGOSTO 2025
E4: Concepto CTA | F4: BANCOS | H4: Bancos | I4: Bancos | J4: Bancos
B5: Fecha | C5: Folio/ Cheque | D5: Tipo | E5: 12061001385 | F5: NOTARIA | H5: EFECTVO | I5: Cheques | J5: SALDO
C6: INGRESO | G6: TRANSFERENCIA | J6: 788122.29
B7: 45870 | C7: 2342 | D7: ingreso | E7: APORTACION DE MIEMBROS | F7: MARIA ZENAIDA VAZQUEZ ALVAREZ | G7: 500 | J7: {=J6+G7} -> 788622.29
B8: 45870 | C8: 2343 | D8: ingreso | E8: APORTACION DE MIEMBROS | F8: VERONICA ILEANA CARRILLO ORTIZ | G8: 500 | J8: {=J7+G8} -> 789122.29
B9: 45876 | D9: ingreso | E9: APORTACION DE MIEMBROS | F9: DEP. EN EFVO. | H9: 500 | J9: {=J8+G9} -> 789122.29
B10: 45880 | D10: ingreso | E10: AFIRME | F10: DEV. DE PAGO ASEGURADORA ZURICH | G10: 10178.42 | J10: {=J9+G10} -> 799300.71
B11: 45883 | D11: ingreso | E11: AFIRME | F11: VENTA TPVCR 09346260 | G11: 50250 | J11: {=J10+G11} -> 849550.71
B12: 45884 | D12: ingreso | E12: AFIRME | F12: VENTA TPVBD 09346260 | G12: 7700 | J12: {=J11+G12} -> 857250.71
B13: 45884 | D13: ingreso | E13: AFIRME | F13: VENTA TPVCR AMX 09346260 | G13: 19550 | J13: {=J12+G13} -> 876800.71
B14: 45884 | C14: 2461 | D14: ingreso | E14: APORTACION DE MIEMBROS | F14: MARIO LOPEZ A LA TORRE | G14: 500 | J14: {=J13+G14} -> 877300.71
B15: 45887 | D15: ingreso | E15: AFIRME | F15: DEV. DE PAGO ASEGURADORA ZURICH | G15: 10178.42 | J15: {=J14+G15} -> 887479.13
B16: 45887 | C16: 2344 | D16: ingreso | E16: APORTACION DE MIEMBROS | F16: ANTONIO MORALES RANGEL | G16: 1500 | J16: {=J15+G16} -> 888979.13
B17: 45887 | C17: 2345 | D17: ingreso | E17: APORTACION DE MIEMBROS | F17: MA. DEL CARMEN OCHOA LEAL | G17: 1500 | J17: {=J16+G17} -> 890479.13
B18: 45887 | C18: 2346 | D18: ingreso | E18: APORTACION DE MIEMBROS | F18: OSCAR GONZALEZ ALANIS | G18: 1000 | J18: {=J17+G18} -> 891479.13
B19: 45887 | C19: 2347 | D19: ingreso | E19: APORTACION DE MIEMBROS | F19: JOSE DE JESUS MARROSU GARZA | G19: 500 | J19: {=J18+G19} -> 891979.13
B20: 45887 | C20: 2348 | D20: ingreso | E20: APORTACION DE MIEMBROS | F20: INES CHI | G20: 500 | J20: {=J19+G20} -> 892479.13
B21: 45894 | D21: ingreso | E21: APORTACION DE MIEMBROS | F21: VENTA TPVCR 09346260 | G21: 500 | J21: {=J20+G21} -> 892979.13
B22: 45894 | D22: ingreso | E22: APORTACION DE MIEMBROS | F22: VENTA TPVDB 09346260 | G22: 500 | J22: {=J21+G22} -> 893479.13
B29: 45880 | D29: egreso | E29: ZURICH ASEGURADORA MEXICANA | F29: SEGURO DE CAMIONETA AVANZA | I29: 10178.42 | J29: {=J22-I29} -> 883300.71
B30: 45883 | D30: egreso | E30: A NOSOTROS MISMOS | F30: DISPERSION DE NOMINA | I30: 13502.08 | J30: {=J29-I30} -> 869798.63
B31: 45883 | D31: egreso | E31: AFIRME | F31: COM. E IVA DE DISPERSION DE FONDOS | I31: 11.6 | J31: {=J30-I31} -> 869787.03
B32: 45884 | D32: egreso | E32: AFIRME | F32: COM. E IVA VTA. TPVCR 09346260 | I32: 1165.8 | J32: {=J31-I32} -> 868621.23
B33: 45884 | D33: egreso | E33: AFIRME | F33: COM. E IVA VENTA TPVDB 09346260 | I33: 169.7 | J33: {=J32-I33} -> 868451.53
B34: 45884 | D34: egreso | E34: AFIRME | F34: COM. E IVA VENTA TPVCR AMX 09346260 | I34: 669.01 | J34: {=J33-I34} -> 867782.52
B35: 45884 | D35: egreso | E35: ELECTRO 2000 | F35: ARREGLO DE FALLA DE INTERRUPTOR CFE | I35: 15057.03 | J35: {=J34-I35} -> 852725.49
B36: 45887 | D36: egreso | E36: ASEGURADORA MEXICANA ZURICH | F36: SEGURO CAMIONETA AVANZA | I36: 10178.42 | J36: {=J35-I36} -> 842547.07
B37: 45888 | D37: egreso | E37: ASEGURADORA MEXICANA ZURICH | F37: SEGURO CAMIONETA AVANZA | I37: 10178.42 | J37: {=J36-I37} -> 832368.65
B38: 45891 | D38: egreso | E38: JORGE DANIEL MEDELLIN LIÑAN | F38: PAGO DE MURO Y SITE DE CAMARAS | I38: 12298 | J38: {=J37-I38} -> 820070.65
B39: 45891 | D39: egreso | E39: JOSE EVERT CRUZ OLGUIN | F39: INSTALACION DE CLIMAS | I39: 7656 | J39: {=J38-I39} -> 812414.65
B40: 45894 | D40: egreso | E40: AFIRME | F40: COM. E IVA VENTA TPVCR 09346260 | I40: 11.6 | J40: {=J39-I40} -> 812403.05
B41: 45894 | D41: egreso | E41: AFIRME | F41: COM. E IVA VENTA TPVDB 09346260 | I41: 11.02 | J41: {=J40-I41} -> 812392.03
... B44: 45898 | D44: egreso | E44: AFIRME | F44: COM. E IVA DISPERSION DE FONDOS | I44: 11.6 | J44: {=J43-I44} -> 798443.3
F50: 0 | H50: CARGOS | J50: BANCO
E51: SIN RECIBO C AFI | F51: 5250 | H51: AF. TD, TC | I51: 0 | J51: 0
E52: CAR TIMBRADO | F52: 56850 | H52: AF. AMEX | I52: 0 | J52: 0
E53: TRANF. DIRECTO PARA T | F53: 6500 | H53: P. TD,AMEX | I53: 0
E54: EFECTIVO | F54: 500 | H54: P. AMEX | I54: 0
...

Sheet SEPTIEMBRE
B2: CONSTRUYENDO LAZOS LA ESTANZUELA AC
B3: Libro de Entradas y Salidas Correspondiente al Mes de SEPTIEMBRE 2025
E4: Concepto CTA | F4: BANCOS | H4: Bancos | I4: Bancos | J4: Bancos
B5: Fecha | C5: Folio/ Cheque | D5: Tipo | E5: 12061001385 | F5: NOTARIA | H5: EFECTVO | I5: Cheques | J5: SALDO
C6: INGRESO | G6: TRANSFERENCIA | J6: {=799945.3-1500} -> 798445.3
B7: 45901 | D7: ingreso | E7: APORTACION DE MIEMBROS | F7: DOLORES LOPEZ GUEVARA | H7: 1500 | J7: {=J6+H7} -> 799945.3
B8: 45901 | D8: ingreso | E8: APORTACION DE MIEMBROS | F8: FLORINDA CARCAÑO SALAZAR | H8: 1000 | J8: {=J7+H8} -> 800945.3
B9: 45901 | C9: 2464 | D9: ingreso | E9: APORTACION DE MIEMBROS | F9: ZENAIDA VAZQUEZ ALVAREZ | G9: 500 | J9: {=J8+G9} -> 801445.3
B10: 45902 | D10: ingreso | E10: APORTACION DE MIEMBROS | H10: 500 | J10: {=J9+H10} -> 801945.3
B11: 45908 | C11: 2465 | D11: ingreso | E11: APORTACION DE MIEMBROS | F11: VERONICA ILEANA CARRILLO ORTIZ | G11: 500 | J11: {=J10+G11} -> 802445.3
B12: 45908 | D12: ingreso | E12: APORTACION DE MIEMBROS | F12: SOCORRO CONTRERAS | G12: 0 | H12: 1000 | J12: {=J11+H12} -> 803445.3
B13: 45915 | D13: ingreso | E13: AFIRME | F13: VENTA TPVCR AMX 09346260 | G13: 20050 | J13: {=J12+G13} -> 823495.3
B14: 45915 | D14: ingreso | E14: AFIRME | F14: VENTA TPVCR AMX 09346260 | G14: 49500 | J14: {=J13+G14} -> 872995.3
B15: 45915 | D15: ingreso | E15: AFIRME | F15: VENTA TPVCR AMX 09346260 | G15: 7200 | J15: {=J14+G15} -> 880195.3
B16: 45915 | C16: 2466 | D16: ingreso | E16: APORTACION DE MIEMBROS | F16: MARIO LOPEZ ALATORRE | G16: 500 | J16: {=J15+G16} -> 880695.3
B17: 45917 | C17: 2469 | D17: ingreso | E17: APORTACION DE MIEMBROS | F17: Antonio Morles 2821393438160113229 | G17: 1500 | J17: {=J16+G17} -> 882195.3
B18: 45917 | D18: ingreso | E18: AFIRME | F18: DEV. NOMINA DEL 150925 | G18: 7001.08 | J18: {=J17+G18} -> 889196.38
B19: 45917 | C19: 2467 | D19: ingreso | E19: APORTACION DE MIEMBROS | F19: INES CHI SANTANDER | G19: 500 | J19: {=J18+G19} -> 889696.38
B20: 45917 | D20: ingreso | E20: APORTACION DE MIEMBROS | F20: MARTHA MEZA | G20: 0 | H20: 1000 | J20: {=J19+H20} -> 890696.38
B21: 45917 | C21: 2468 | D21: ingreso | E21: APORTACION DE MIEMBROS | F21: OSCAR GONZALEZ ALANIS | G21: 1000 | J21: {=J20+G21} -> 891696.38
B22: 45918 | D22: ingreso | E22: DEPOSITO EFECTIVO | F22: DEV. NOMINA DEL 150925 | H22: 6500.9 | J22: {=J21+H22} -> 898197.28
B23: 45919 | C23: 2470 | D23: ingreso | E23: APORTACION DE MIEMBROS | F23: MARIA DEL CARMEN OCHOA | G23: 1500 | J23: {=J22+G23} -> 899697.28
B24: 45922 | D24: ingreso | E24: APORTACION DE MIEMBROS | F24: ELIAS MARTINEZ DN. ANUAL 2026 | H24: 6000 | J24: {=J23+H24} -> 905697.28
B25: 45922 | D25: ingreso | E25: TOREO MOTORS SA DE CV | F25: DEV. DEPOSITO EN GARANTIA | G25: 5000 | J25: {=J24+G25} -> 910697.28
B34: 45908 | D34: egreso | E34: LONAS Y ESTRUCTURAS CANTU | F34: ANT. RENTA DE LONAS, BENDICION 1 PIED. | I34: 20880 | J34: {=J25-I34} -> 889817.28
B35: 45909 | D35: egreso | E35: RALIGU SA DE CV | F35: TRABAJO DE ESCALINATAS Y BANQUETES | I35: 196245.55 | J35: {=J34-I35} -> 693571.73
B36: 45909 | D36: egreso | E36: JOSE RAMIRO | F36: COMPRA DE TONER | I36: 1100 | J36: {=J35-I36} -> 692471.73
B37: 45910 | D37: egreso | E37: SANI REY | F37: RENTA DE SANITARIOS | I37: 5916 | J37: {=J36-I37} -> 686555.73
B38: 45915 | D38: egreso | E38: AFIRME | F38: COMVTA TPVCR AMX 09346260 | I38: 591.48 | J38: {=J37-I38} -> 685964.25
B39: 45915 | D39: egreso | E39: AFIRME | F39: IVA COMVTA TPVCR AMX | I39: 94.64 | J39: {=J38-I39} -> 685869.61
B40: 45915 | D40: egreso | E40: AFIRME | F40: COMVTA TPVCR 09346260 | I40: 990 | J40: {=J39-I40} -> 684879.61
B41: 45915 | D41: egreso | E41: AFIRME | F41: IVA COMVTA TPVCR 09346260 | I41: 158.4 | J41: {=J40-I41} -> 684721.21
B42: 45915 | D42: egreso | E42: AFIRME | F42: COMVTA TPVDB 09346260 | I42: 136.8 | J42: {=J41-I42} -> 684584.41
B43: 45915 | D43: egreso | E43: AFIRME | F43: IVA COMVTA TPVDB 09346260 | I43: 21.88 | J43: {=J42-I43} -> 684562.53
B44: 45915 | D44: egreso | E44: A NOSOTROS MISMOS | F44: DISPERSION DE FONDOS | I44: 13502.08 | J44: {=J43-I44} -> 671060.45
B45: 45915 | D45: egreso | E45: AFIRME | F45: COMISION E IVA DISPERSION DE FONDOS | I45: 11.6 | J45: {=J44-I45} -> 671048.85
B46: 45915 | D46: egreso | E46: A NOSOTROS MISMOS | F46: DISPERSION DE FONDOS | I46: 13501.98 | J46: {=J45-I46} -> 657546.87
... B51: 45919 | D51: egreso | E51: ACEROS Y MATERIALES MACH SA DE CV | F51: PAGO DE GRUA | I51: 6380 | J51: {=J50-I51} -> 626415.27
B52: 45919 | D52: egreso | E52: LONAS Y ESTRUCTURAS CANTU | I52: 20880 | J52: {=J51-I52} -> 605535.27
B53: 45924 | D53: egreso | E53: ZURICH ASEGURADORA MEXICANA | F53: PAGO SEGURO DE CAMIONETA AVANZA | I53: 9869.84 | J53: {=J52-I53} -> 595665.43
...

Sheet OCTUBRE
B2: CONSTRUYENDO LAZOS LA ESTANZUELA AC
B3: Libro de Entradas y Salidas Correspondiente al Mes de OCTUBRE 2025
E4: Concepto CTA | F4: BANCOS | H4: Bancos | I4: Bancos | J4: Bancos
B5: Fecha | C5: Folio/ Cheque | D5: Tipo | E5: 12061001385 | F5: NOTARIA | H5: EFECTVO | I5: Cheques | J5: SALDO
C6: INGRESO | G6: TRANSFERENCIA | J6: 552223.75
B7: 45931 | D7: ingreso | E7: APORTACION DE MIEMBROS | F7: REYNA ESQUIVEL | H7: 500 | J7: {=J6+H7} -> 552723.75
B8: 45936 | C8: 2571 | D8: ingreso | E8: APORTACION DE MIEMBROS | F8: MARIA ZENAIDA VAZQUEZ ALVAREZ | G8: 500 | J8: {=J7+G8} -> 553223.75
B9: 45938 | C9: 2572 | D9: ingreso | E9: APORTACION DE MIEMBROS | F9: INES CHI SANTANDER | G9: 500 | J9: {=J8+G9} -> 553723.75
B10: 45943 | D10: ingreso | E10: APORTACION DE MIEMBROS | F10: SOCORRO CONTRERAS | H10: 500 | J10: {=J9+H10} -> 554223.75
B11: 45945 | C11: 2573 | D11: ingreso | E11: APORTACION DE MIEMBROS | F11: MARIO LOPEZ ALATORRE | G11: 500 | J11: {=J10+G11} -> 554723.75
B12: 45945 | C12: 2574 | D12: ingreso | E12: APORTACION DE MIEMBROS | F12: OSCAR GONZALEZ ALANIS | G12: 1000 | J12: {=J11+G12} -> 555723.75
B13: 45947 | D13: ingreso | E13: AFIRME | F13: VENTA TPVCR 09346260 | G13: 47300 | J13: {=J12+G13} -> 603023.75
B14: 45947 | D14: ingreso | E14: AFIRME | F14: VENTA TPVCB 09346260 | G14: 7200 | J14: {=J13+G14} -> 610223.75
B15: 45947 | D15: ingreso | E15: AFIRME | F15: VENTA TPVCR AMX 09346260 | G15: 19550 | J15: {=J14+G15} -> 629773.75
B16: 45950 | D16: ingreso | E16: APORTACION DE MIEMBROS | H16: 500 | J16: {=J15+H16} -> 630273.75
B17: 45950 | D17: ingreso | E17: APORTACION DE MIEMBROS | F17: MA. DEL CARMEN OCHOA LEAL | G17: 1500 | J17: {=J16+G17} -> 631773.75
B18: 45950 | D18: ingreso | E18: APORTACION DE MIEMBROS | F18: LUPITA GUEVARA Y REYNA ESQUIVEL | H18: 1000 | J18: {=J17+H18} -> 632773.75
B19: 45951 | D19: ingreso | E19: APORTACION DE MIEMBROS | F19: SOCORRO CONTRERAS | H19: 500 | J19: {=J18+H19} -> 633273.75
D20: ingreso | J20: {=J19+G20} -> 633273.75
J21: {=J20+G21} -> 633273.75
J22: {=J21+G22} -> 633273.75
J23: {=J22+G23} -> 633273.75
J24: {=J23+H24} -> 633273.75
J25: {=J24+G25} -> 633273.75
J26: {=J25+G26} -> 633273.75
J27: {=J26+G27} -> 633273.75
J28: {=J27+G28} -> 633273.75
J29: {=J28+G29} -> 633273.75
J30: {=J29+G30} -> 633273.75
B34: 45931 | D34: egreso | E34: DANIEL FLORES ZUÑIGA | F34: CAMARAS, HDMI | I34: 7466.78 | J34: {=J30-I34} -> 625806.97
B35: 45940 | D35: egreso | E35: GLORIA ZAPATA | F35: PAGO DE PAPELERIA | I35: 4640 | J35: {=J34-I35} -> 621166.97
B36: 45943 | D36: egreso | E36: BANORTE | F36: TRASPASO A CUENTA PROPIA | I36: 10000 | J36: {=J35-I36} -> 611166.97
B37: 45944 | D37: egreso | E37: A NOSOTROS MISMOS | F37: DISPERSION DE FONDOS | I37: 13502.08 | J37: {=J36-I37} -> 597664.89
B38: 45944 | D38: egreso | E38: AFIRME | F38: COMISION E IVA DE DISPERSION DE FONDOS | I38: 11.6 | J38: {=J37-I38} -> 597653.29
B39: 45947 | D39: egreso | E39: AFIRME | F39: COMVTA TPVCR 09346260 | I39: 946 | J39: {=J38-I39} -> 596707.29
B40: 45947 | D40: egreso | E40: AFIRME | F40: IVA COMVTA TPVCR 09346260 | I40: 151.36 | J40: {=J39-I40} -> 596555.93
B41: 45947 | D41: egreso | E41: AFIRME | F41: COMVTA TPVCB 09346260 | I41: 136.8 | J41: {=J40-I41} -> 596419.13
B42: 45947 | D42: egreso | E42: AFIRME | F42: IVA COMVTA TPVCB 09346260 | I42: 21.88 | J42: {=J41-I42} -> 596397.25
B43: 45947 | D43: egreso | E43: AFIRME | F43: COMVTA TPVCR AMX | I43: 576.73 | J43: {=J42-I43} -> 595820.52
B44: 45947 | D44: egreso | E44: AFIRME | F44: IVA COMVTA TPVCR AMX | I44: 92.28 | J44: {=J43-I44} -> 595728.24
...

Sheet NOVIEMBRE

Sheet DICIEMBRE
